2024-03-05 17:26:38,461 INFO    MainThread:3693451 [internal.py:wandb_internal():88] W&B internal server running at pid: 3693451, started at: 2024-03-05 17:26:38.460697
2024-03-05 17:26:38,463 DEBUG   HandlerThread:3693451 [handler.py:handle_request():124] handle_request: check_version
2024-03-05 17:26:38,463 INFO    WriterThread:3693451 [datastore.py:open_for_write():80] open: /trinity/home/a.kolesov/NOTBarycenters/stylegan2/notebooks/wandb/run-20240305_172637-r4tk6oh2/run-r4tk6oh2.wandb
2024-03-05 17:26:38,466 DEBUG   SenderThread:3693451 [sender.py:send():179] send: header
2024-03-05 17:26:38,466 DEBUG   SenderThread:3693451 [sender.py:send_request():193] send_request: check_version
2024-03-05 17:26:38,580 DEBUG   SenderThread:3693451 [sender.py:send():179] send: run
2024-03-05 17:26:38,812 ERROR   SenderThread:3693451 [internal_api.py:execute():130] 404 response executing GraphQL.
2024-03-05 17:26:38,813 ERROR   SenderThread:3693451 [internal_api.py:execute():131] {"errors":[{"message":"project not found","path":["upsertBucket"]}],"data":{"upsertBucket":null}}
2024-03-05 17:26:39,580 INFO    WriterThread:3693451 [datastore.py:close():288] close: /trinity/home/a.kolesov/NOTBarycenters/stylegan2/notebooks/wandb/run-20240305_172637-r4tk6oh2/run-r4tk6oh2.wandb
2024-03-05 17:26:39,581 INFO    HandlerThread:3693451 [handler.py:finish():638] shutting down handler
2024-03-05 17:26:39,582 ERROR   MainThread:3693451 [internal.py:wandb_internal():159] Thread SenderThread:
Traceback (most recent call last):
  File "/opt/anaconda3/lib/python3.8/site-packages/wandb/sdk/lib/retry.py", line 102, in __call__
    result = self._call_fn(*args, **kwargs)
  File "/opt/anaconda3/lib/python3.8/site-packages/wandb/sdk/internal/internal_api.py", line 133, in execute
    six.reraise(*sys.exc_info())
  File "/opt/anaconda3/lib/python3.8/site-packages/six.py", line 703, in reraise
    raise value
  File "/opt/anaconda3/lib/python3.8/site-packages/wandb/sdk/internal/internal_api.py", line 127, in execute
    return self.client.execute(*args, **kwargs)
  File "/opt/anaconda3/lib/python3.8/site-packages/wandb/vendor/gql-0.2.0/gql/client.py", line 52, in execute
    result = self._get_result(document, *args, **kwargs)
  File "/opt/anaconda3/lib/python3.8/site-packages/wandb/vendor/gql-0.2.0/gql/client.py", line 60, in _get_result
    return self.transport.execute(document, *args, **kwargs)
  File "/opt/anaconda3/lib/python3.8/site-packages/wandb/vendor/gql-0.2.0/gql/transport/requests.py", line 39, in execute
    request.raise_for_status()
  File "/opt/anaconda3/lib/python3.8/site-packages/requests/models.py", line 943, in raise_for_status
    raise HTTPError(http_error_msg, response=self)
requests.exceptions.HTTPError: 404 Client Error: Not Found for url: https://api.wandb.ai/graphql

During handling of the above exception, another exception occurred:

Traceback (most recent call last):
  File "/opt/anaconda3/lib/python3.8/site-packages/wandb/apis/normalize.py", line 24, in wrapper
    return func(*args, **kwargs)
  File "/opt/anaconda3/lib/python3.8/site-packages/wandb/sdk/internal/internal_api.py", line 922, in upsert_run
    response = self.gql(mutation, variable_values=variable_values, **kwargs)
  File "/opt/anaconda3/lib/python3.8/site-packages/wandb/sdk/lib/retry.py", line 118, in __call__
    if not check_retry_fn(e):
  File "/opt/anaconda3/lib/python3.8/site-packages/wandb/util.py", line 727, in no_retry_auth
    raise CommError("Permission denied, ask the project owner to grant you access")
wandb.errors.CommError: Permission denied, ask the project owner to grant you access

During handling of the above exception, another exception occurred:

Traceback (most recent call last):
  File "/opt/anaconda3/lib/python3.8/site-packages/wandb/sdk/internal/internal_util.py", line 55, in run
    self._run()
  File "/opt/anaconda3/lib/python3.8/site-packages/wandb/sdk/internal/internal_util.py", line 105, in _run
    self._process(record)
  File "/opt/anaconda3/lib/python3.8/site-packages/wandb/sdk/internal/internal.py", line 292, in _process
    self._sm.send(record)
  File "/opt/anaconda3/lib/python3.8/site-packages/wandb/sdk/internal/sender.py", line 181, in send
    send_handler(record)
  File "/opt/anaconda3/lib/python3.8/site-packages/wandb/sdk/internal/sender.py", line 604, in send_run
    self._init_run(run, config_value_dict)
  File "/opt/anaconda3/lib/python3.8/site-packages/wandb/sdk/internal/sender.py", line 626, in _init_run
    server_run, inserted = self._api.upsert_run(
  File "/opt/anaconda3/lib/python3.8/site-packages/wandb/apis/normalize.py", line 62, in wrapper
    six.reraise(CommError, CommError(message, err), sys.exc_info()[2])
  File "/opt/anaconda3/lib/python3.8/site-packages/six.py", line 702, in reraise
    raise value.with_traceback(tb)
  File "/opt/anaconda3/lib/python3.8/site-packages/wandb/apis/normalize.py", line 24, in wrapper
    return func(*args, **kwargs)
  File "/opt/anaconda3/lib/python3.8/site-packages/wandb/sdk/internal/internal_api.py", line 922, in upsert_run
    response = self.gql(mutation, variable_values=variable_values, **kwargs)
  File "/opt/anaconda3/lib/python3.8/site-packages/wandb/sdk/lib/retry.py", line 118, in __call__
    if not check_retry_fn(e):
  File "/opt/anaconda3/lib/python3.8/site-packages/wandb/util.py", line 727, in no_retry_auth
    raise CommError("Permission denied, ask the project owner to grant you access")
wandb.errors.CommError: Permission denied, ask the project owner to grant you access
2024-03-05 17:26:41,597 INFO    MainThread:3693451 [internal.py:handle_exit():78] Internal process exited
